Workbook

Sheet Charts  ST Demand & Market Tigh
A1: Year | B1: ExchangeRate (Export Competitors - Corn) | C1: Ending Stocks | D1: World: Ending Stocks | E1: World Pop (SPPOPTOTLWLD) | F1: US pop (1000s) (B230RC0A052NBEA) | G1: USGDP (GDP) | H1: PCE Index (PCEPI) | I1: Total Usage | J1: Real MYA Price | K1: Supply | L1: Supply Index | M1: Invert Supply | N1: Elasticity | O1: -0.16565854 | Q1: p^-.17 (P epsolon) | R1: A | S1: Demand Index | T1: (From earlier efforts | V1: Supply/Demand Strengh | X1: S/D Index | AD1: Sup2Usage
A2: 2000 | B2: 110.65269 | C2: 48240 | D2: 175136 | E2: 6161884811 | F2: 282398 | G2: 10250.952 | H2: 73.822 | I2: 2803.7648 | J2: 9.0152456 | K2: 3051.5275 | L2: =(K2/$K$11)*100 -> 86.845903 | M2: =100-(L2-100) -> 113.1541 | N2: inverted elasticiy | O2: =1/O1 -> -6.0365133 | P2: 2000 | Q2: =J2^$O$1 -> 0.69470401 | R2: =I2/Q2 -> 4035.9127 | S2: =(R2/$R$11)*100 -> 76.912166 | V2: =K2/R2 -> 0.75609354 | W2: =V2^$O$2 -> 5.4072998 | X2: =(W2/$W$11)*100 -> 48.033919 | AB2: =K2-I2 -> 247.76277 | AC2: =(I2/K2)*100 -> 91.880697 | AD2: =(AC2/$AC$28)*100 -> 99.148416 | AE2: 100
A3: 2001 | B3: 117.24628 | C3: 40551 | D3: 151409 | E3: 6245112906 | F3: 285225 | G3: 10581.929 | H3: 75.302 | I3: 2932.6984 | J3: 8.4303226 | K3: 3140.778 | L3: =(K3/$K$11)*100 -> 89.385954 | M3: =100-(L3-100) -> 110.61405 | P3: 2001 | Q3: =J3^$O$1 -> 0.70246712 | R3: =I3/Q3 -> 4174.8551 | S3: =(R3/$R$11)*100 -> 79.559983 | V3: =K3/R3 -> 0.75230827 | W3: =V3^$O$2 -> 5.5736307 | X3: =(W3/$W$11)*100 -> 49.511464 | AB3: =K3-I3 -> 208.07957 | AC3: =(I3/K3)*100 -> 93.374903 | AD3: =(AC3/$AC$28)*100 -> 100.76081 | AE3: 100
A4: 2002 | B4: 103.79282 | C4: 27603 | D4: 126942 | E4: 6327557399 | F4: 287955 | G4: 10929.108 | H4: 76.291 | I4: 2790.5738 | J4: 10.451116 | K4: 2968.891 | L4: =(K4/$K$11)*100 -> 84.494081 | M4: =100-(L4-100) -> 115.50592 | O4: -0.16565854 | P4: 2002 | Q4: =J4^$O$1 -> 0.67790213 | R4: =I4/Q4 -> 4116.4848 | S4: =(R4/$R$11)*100 -> 78.447623 | V4: =K4/R4 -> 0.72121995 | W4: =V4^$O$2 -> 7.1907802 | X4: =(W4/$W$11)*100 -> 63.876865 | AB4: =K4-I4 -> 178.31718 | AC4: =(I4/K4)*100 -> 93.993812 | AD4: =(AC4/$AC$28)*100 -> 101.42868 | AE4: 100
A5: 2003 | B5: 96.601189 | C5: 24337 | D5: 104701 | E5: 6409750441 | F5: 290626 | G5: 11456.45 | H5: 77.894 | I5: 2525.321 | J5: 13.584963 | K5: 2637.72 | L5: =(K5/$K$11)*100 -> 75.069017 | M5: =100-(L5-100) -> 124.93098 | O5: -0.16565854 | P5: 2003 | Q5: =J5^$O$1 -> 0.64908143 | R5: =I5/Q5 -> 3890.6074 | S5: =(R5/$R$11)*100 -> 74.14309 | V5: =K5/R5 -> 0.67797126 | W5: =V5^$O$2 -> 10.444685 | X5: =(W5/$W$11)*100 -> 92.781824 | AB5: =K5-I5 -> 112.39898 | AC5: =(I5/K5)*100 -> 95.738783 | AD5: =(AC5/$AC$28)*100 -> 103.31168 | AE5: 100
A6: 2004 | B6: 92.980888 | C6: 53697 | D6: 131156 | E6: 6492769815 | F6: 293262 | G6: 12217.196 | H6: 79.827 | I6: 2986.0503 | J6: 10.2746 | K6: 3241.7864 | L6: =(K6/$K$11)*100 -> 92.260635 | M6: =100-(L6-100) -> 107.73937 | P6: 2004 | Q6: =J6^$O$1 -> 0.67981775 | R6: =I6/Q6 -> 4392.4277 | S6: =(R6/$R$11)*100 -> 83.706252 | V6: =K6/R6 -> 0.7380398 | W6: =V6^$O$2 -> 6.2565966 | X6: =(W6/$W$11)*100 -> 55.578361 | AB6: =K6-I6 -> 255.73615 | AC6: =(I6/K6)*100 -> 92.111258 | AD6: =(AC6/$AC$28)*100 -> 99.397215 | AE6: 100
A7: 2005 | B7: 91.054237 | C7: 49968 | D7: 123418 | E7: 6575841506 | F7: 295993 | G7: 13039.197 | H7: 82.127 | I7: 2878.134 | J7: 9.8911855 | K7: 3327.4727 | L7: =(K7/$K$11)*100 -> 94.699251 | M7: =100-(L7-100) -> 105.30075 | P7: 2005 | Q7: =J7^$O$1 -> 0.68411421 | R7: =I7/Q7 -> 4207.0958 | S7: =(R7/$R$11)*100 -> 80.174393 | V7: =K7/R7 -> 0.79091917 | W7: =V7^$O$2 -> 4.1202819 | X7: =(W7/$W$11)*100 -> 36.601131 | AB7: =K7-I7 -> 449.33871 | AC7: =(I7/K7)*100 -> 86.496096 | AD7: =(AC7/$AC$28)*100 -> 93.337897 | AE7: 100
A8: 2006 | B8: 84.098709 | C8: 33114 | D8: 108756 | E8: 6659977025 | F8: 298818 | G8: 13815.583 | H8: 84.44 | I8: 3081.2899 | J8: 10.976553 | K8: 3655.1163 | L8: =(K8/$K$11)*100 -> 104.02393 | M8: =100-(L8-100) -> 95.976074 | P8: 2006 | Q8: =J8^$O$1 -> 0.67241582 | R8: =I8/Q8 -> 4582.4174 | S8: =(R8/$R$11)*100 -> 87.326876 | V8: =K8/R8 -> 0.79763932 | W8: =V8^$O$2 -> 3.9151286 | X8: =(W8/$W$11)*100 -> 34.778721 | AB8: =K8-I8 -> 573.82636 | AC8: =(I8/K8)*100 -> 84.300736 | AD8: =(AC8/$AC$28)*100 -> 90.968884 | AE8: 100
A9: 2007 | B9: 79.869598 | C9: 41255 | D9: 125362 | E9: 6744489399 | F9: 301696 | G9: 14474.227 | H9: 86.607 | I9: 3055.7898 | J9: 16.586239 | K9: 3260.8197 | L9: =(K9/$K$11)*100 -> 92.802317 | M9: =100-(L9-100) -> 107.19768 | P9: 2007 | Q9: =J9^$O$1 -> 0.62796919 | R9: =I9/Q9 -> 4866.1461 | S9: =(R9/$R$11)*100 -> 92.733877 | V9: =K9/R9 -> 0.67010312 | W9: =V9^$O$2 -> 11.20723 | X9: =(W9/$W$11)*100 -> 99.555642 | AB9: =K9-I9 -> 205.02985 | AC9: =(I9/K9)*100 -> 93.712322 | AD9: =(AC9/$AC$28)*100 -> 101.12492 | AE9: 100
A10: 2008 | B10: 84.344528 | C10: 42504 | D10: 136049 | E10: 6830513541 | F10: 304543 | G10: 14769.862 | H10: 89.17 | I10: 3047.1183 | J10: 15.537823 | K10: 3185.3114 | L10: =(K10/$K$11)*100 -> 90.653365 | M10: =100-(L10-100) -> 109.34663 | P10: 2008 | Q10: =J10^$O$1 -> 0.63479871 | R10: =I10/Q10 -> 4800.1331 | S10: =(R10/$R$11)*100 -> 91.475871 | V10: =K10/R10 -> 0.66358814 | W10: =V10^$O$2 -> 11.888071 | X10: =(W10/$W$11)*100 -> 105.60366 | AB10: =K10-I10 -> 138.19306 | AC10: =(I10/K10)*100 -> 95.661553 | AD10: =(AC10/$AC$28)*100 -> 103.22834 | AE10: 100
A11: 2009 | B11: 82.045845 | C11: 43380 | D11: 131485 | E11: 6916589116 | F11: 307240 | G11: 14478.067 | H11: 88.921 | I11: 3362.8569 | J11: 14.67188 | K11: 3513.7265 | L11: =(K11/$K$11)*100 -> 100 | M11: =100-(L11-100) -> 100 | P11: 2009 | Q11: =J11^$O$1 -> 0.64085779 | R11: =I11/Q11 -> 5247.4308 | S11: =(R11/$R$11)*100 -> 100 | T11: 100.85527 | V11: =K11/R11 -> 0.66960893 | W11: =V11^$O$2 -> 11.257253 | X11: =(W11/$W$11)*100 -> 100 | AB11: =K11-I11 -> 150.86963 | AC11: =(I11/K11)*100 -> 95.706278 | AD11: =(AC11/$AC$28)*100 -> 103.2766 | AE11: 100
A12: 2010 | B12: 78.3582 | C12: 28644 | D12: 114858 | E12: 7001266876 | F12: 309839 | G12: 15048.971 | H12: 90.514 | I12: 3281.5798 | J12: 17.162303 | K12: 3496.604 | L12: =(K12/$K$11)*100 -> 99.512695 | M12: =100-(L12-100) -> 100.4873 | P12: 2010 | Q12: =J12^$O$1 -> 0.62442748 | R12: =I12/Q12 -> 5255.3418 | S12: =(R12/$R$11)*100 -> 100.15076 | T12: 104.36824 | V12: =K12/R12 -> 0.66534283 | W12: =V12^$O$2 -> 11.700066 | X12: =(W12/$W$11)*100 -> 103.93358 | AB12: =K12-I12 -> 215.02413 | AC12: =(I12/K12)*100 -> 93.850487 | AD12: =(AC12/$AC$28)*100 -> 101.27402 | AE12: 100
A13: 2011 | B13: 83.05545 | C13: 25122 | D13: 122848 | E13: 7087120034 | F13: 312295 | G13: 15599.732 | H13: 92.804 | I13: 3158.9294 | J13: 18.318713 | K13: 3328.3178 | L13: =(K13/$K$11)*100 -> 94.723303 | M13: =100-(L13-100) -> 105.2767 | P13: 2011 | Q13: =J13^$O$1 -> 0.61771857 | R13: =I13/Q13 -> 5113.865 | S13: =(R13/$R$11)*100 -> 97.454643 | T13: 97.927618 | V13: =K13/R13 -> 0.65084195 | W13: =V13^$O$2 -> 13.364645 | X13: =(W13/$W$11)*100 -> 118.7203 | AB13: =K13-I13 -> 169.38846 | AC13: =(I13/K13)*100 -> 94.910689 | AD13: =(AC13/$AC$28)*100 -> 102.41808 | AE13: 100
A14: 2012 | B14: 83.028945 | C14: 20859 | D14: 145530 | E14: 7176929184 | F14: 314725 | G14: 16253.97 | H14: 94.534 | I14: 3111.4198 | J14: 20.59726 | K14: 3251.9644 | L14: =(K14/$K$11)*100 -> 92.550299 | M14: =100-(L14-100) -> 107.4497 | P14: 2012 | Q14: =J14^$O$1 -> 0.60583762 | R14: =I14/Q14 -> 5135.7322 | S14: =(R14/$R$11)*100 -> 97.871365 | T14: 72.56313 | V14: =K14/R14 -> 0.63320366 | W14: =V14^$O$2 -> 15.775597 | X14: =(W14/$W$11)*100 -> 140.13718 | AB14: =K14-I14 -> 140.54465 | AC14: =(I14/K14)*100 -> 95.678161 | AD14: =(AC14/$AC$28)*100 -> 103.24626 | AE14: 100
A15: 2013 | B15: 86.381657 | C15: 31292 | D15: 216040 | E15: 7265892332 | F15: 317099 | G15: 16880.683 | H15: 95.781 | I15: 3477.3135 | J15: 18.322835 | K15: 3569.3198 | L15: =(K15/$K$11)*100 -> 101.58217 | M15: =100-(L15-100) -> 98.417827 | P15: 2013 | Q15: =J15^$O$1 -> 0.61769555 | R15: =I15/Q15 -> 5629.4942 | S15: =(R15/$R$11)*100 -> 107.28096 | T15: 89.785653 | V15: =K15/R15 -> 0.63403916 | W15: =V15^$O$2 -> 15.650525 | X15: =(W15/$W$11)*100 -> 139.02615 | AB15: =K15-I15 -> 92.006225 | AC15: =(I15/K15)*100 -> 97.422304 | AD15: =(AC15/$AC$28)*100 -> 105.12836 | AE15: 100
A16: 2014 | B16: 99.928975 | C16: 43974 | D16: 279937 | E16: 7354068030 | F16: 319601 | G16: 17608.138 | H16: 97.121 | I16: 3862.6815 | J16: 13.922222 | K16: 4053.3078 | L16: =(K16/$K$11)*100 -> 115.35638 | M16: =100-(L16-100) -> 84.643619 | P16: 2014 | Q16: =J16^$O$1 -> 0.64644995 | R16: =I16/Q16 -> 5975.2212 | S16: =(R16/$R$11)*100 -> 113.86946 | T16: 87.842946 | V16: =K16/R16 -> 0.67835275 | W16: =V16^$O$2 -> 10.409277 | X16: =(W16/$W$11)*100 -> 92.467291 | AB16: =K16-I16 -> 190.62632 | AC16: =(I16/K16)*100 -> 95.297018 | AD16: =(AC16/$AC$28)*100 -> 102.83497 | AE16: 100
A17: 2015 | B17: 103.52059 | C17: 44123 | D17: 313363 | E17: 7441677465 | F17: 322113 | G17: 18295.019 | H17: 97.299 | I17: 3944.2157 | J17: 12.110529 | K17: 4140.9415 | L17: =(K17/$K$11)*100 -> 117.85042 | M17: =100-(L17-100) -> 82.14958 | P17: 2015 | Q17: =J17^$O$1 -> 0.6615532 | R17: =I17/Q17 -> 5962.0537 | S17: =(R17/$R$11)*100 -> 113.61853 | T17: 81.84277 | V17: =K17/R17 -> 0.69454951 | W17: =V17^$O$2 -> 9.0273583 | X17: =(W17/$W$11)*100 -> 80.191485 | AB17: =K17-I17 -> 196.72577 | AC17: =(I17/K17)*100 -> 95.24925 | AD17: =(AC17/$AC$28)*100 -> 102.78342 | AE17: 100
A18: 2016 | B18: 100.41136 | C18: 58253 | D18: 350824 | E18: 7528879985 | F18: 324609 | G18: 18804.913 | H18: 98.284 | I18: 4213.8777 | J18: 12.772777 | K18: 4515.47 | L18: =(K18/$K$11)*100 -> 128.50943 | M18: =100-(L18-100) -> 71.490568 | P18: 2016 | Q18: =J18^$O$1 -> 0.65574409 | R18: =I18/Q18 -> 6426.101 | S18: =(R18/$R$11)*100 -> 122.46185 | T18: 88.936169 | V18: =K18/R18 -> 0.70267648 | W18: =V18^$O$2 -> 8.4151715 | X18: =(W18/$W$11)*100 -> 74.753331 | AB18: =K18-I18 -> 301.59229 | AC18: =(I18/K18)*100 -> 93.32091 | AD18: =(AC18/$AC$28)*100 -> 100.70255 | AE18: 100
A19: 2017 | B19: 102.30157 | C19: 54367 | D19: 342235 | E19: 7614523410 | F19: 326860 | G19: 19612.103 | H19: 100 | I19: 4296.9553 | J19: 12.47651 | K19: 4735.0504 | L19: =(K19/$K$11)*100 -> 134.75865 | M19: =100-(L19-100) -> 65.241352 | P19: 2017 | Q19: =J19^$O$1 -> 0.65829842 | R19: =I19/Q19 -> 6527.3668 | S19: =(R19/$R$11)*100 -> 124.39167 | T19: 92.283147 | V19: =K19/R19 -> 0.72541509 | W19: =V19^$O$2 -> 6.9433801 | X19: =(W19/$W$11)*100 -> 61.67917 | AB19: =K19-I19 -> 438.09514 | AC19: =(I19/K19)*100 -> 90.747825 | AD19: =(AC19/$AC$28)*100 -> 97.925935 | AE19: 100
A20: 2018 | B20: 108.06282 | C20: 56823 | D20: 326775 | E20: 7697233736 | F20: 328794 | G20: 20656.516 | H20: 102.047 | I20: 3955.2756 | J20: 11.184674 | K20: 4880.335 | L20: =(K20/$K$11)*100 -> 138.89342 | M20: =100-(L20-100) -> 61.10658 | P20: 2018 | Q20: =J20^$O$1 -> 0.67032681 | R20: =I20/Q20 -> 5900.5183 | S20: =(R20/$R$11)*100 -> 112.44585 | T20: 90.264036 | V20: =K20/R20 -> 0.82710276 | W20: =V20^$O$2 -> 3.1452368 | X20: =(W20/$W$11)*100 -> 27.939647 | AB20: =K20-I20 -> 925.05939 | AC20: =(I20/K20)*100 -> 81.045166 | AD20: =(AC20/$AC$28)*100 -> 87.4558 | AE20: 100
A21: 2019 | B21: 112.25717 | C21: 50913 | D21: 314542 | E21: 7778008621 | F21: 330513 | G21: 21539.982 | H21: 103.509 | I21: 3952.9607 | J21: 11.093192 | K21: 4491.5131 | L21: =(K21/$K$11)*100 -> 127.82762 | M21: =100-(L21-100) -> 72.172376 | P21: 2019 | Q21: =J21^$O$1 -> 0.67123943 | R21: =I21/Q21 -> 5889.0473 | S21: =(R21/$R$11)*100 -> 112.22725 | T21: 87.550077 | V21: =K21/R21 -> 0.76268926 | W21: =V21^$O$2 -> 5.1310954 | X21: =(W21/$W$11)*100 -> 45.580351 | AB21: =K21-I21 -> 538.55241 | AC21: =(I21/K21)*100 -> 88.009555 | AD21: =(AC21/$AC$28)*100 -> 94.971069 | AE21: 100
A22: 2020 | B22: 110.50794 | C22: 31358 | D22: 297358 | E22: 7854748424 | F22: 331840 | G22: 21375.282 | H22: 104.666 | I22: 4517.6747 | J22: 13.5324 | K22: 4774.6601 | L22: =(K22/$K$11)*100 -> 135.88593 | M22: =100-(L22-100) -> 64.114067 | P22: 2020 | Q22: =J22^$O$1 -> 0.64949841 | R22: =I22/Q22 -> 6955.6362 | S22: =(R22/$R$11)*100 -> 132.55317 | T22: 107.31693 | V22: =K22/R22 -> 0.68644477 | W22: =V22^$O$2 -> 9.6901936 | X22: =(W22/$W$11)*100 -> 86.079558 | AB22: =K22-I22 -> 256.98544 | AC22: =(I22/K22)*100 -> 94.617723 | AD22: =(AC22/$AC$28)*100 -> 102.10194 | AE22: 100
... A26: 2024 | B26: 115.30512 | C26: 38905 | D26: 293369 | E26: 8141808945 | F26: 340212 | G26: 29298.013 | H26: 123.666 | I26: 4420.8183 | J26: 10.195281 | K26: 4745.6326 | L26: =(K26/$K$11)*100 -> 135.05982 | M26: =100-(L26-100) -> 64.940185 | P26: 2024 | Q26: =J26^$O$1 -> 0.68069108 | R26: =I26/Q26 -> 6494.6029 | S26: =(R26/$R$11)*100 -> 123.76729 | T26: 94.660708 | V26: =K26/R26 -> 0.73070404 | W26: =V26^$O$2 -> 6.6454776 | X26: =(W26/$W$11)*100 -> 59.032854 | AB26: =K26-I26 -> 324.81431 | AC26: =(I26/K26)*100 -> 93.155511 | AD26: =(AC26/$AC$28)*100 -> 100.52407 | AE26: 100
A27: 2025 | B27: 117.66338 | C27: 51534 | D27: 279151 | E27: =AVERAGE((E26-E25),(E25-E24),(E24-E23),(E23-E22))+E26 -> 8.2135741e+09 | F27: =AVERAGE((F26-F25),(F25-F24),(F24-F23),(F23-F22))+F26 -> 342305 | G27: =AVERAGE((G26-G25),(G25-G24),(G24-G23),(G23-G22))+G26 -> 31278.696 | H27: =AVERAGE((H26-H25),(H25-H24),(H24-H23),(H23-H22))+H26 -> 128.416 | I27: 4256.9781 | J27: 10.2 | K27: 4606.6679 | L27: =(K27/$K$11)*100 -> 131.10491 | M27: =100-(L27-100) -> 68.895093 | P27: 2025 | Q27: =J27^$O$1 -> 0.6806389 | R27: =I27/Q27 -> 6254.3856 | S27: =(R27/$R$11)*100 -> 119.18948 | T27: 112.57873 | V27: =K27/R27 -> 0.73655003 | W27: =V27^$O$2 -> 6.3333774 | X27: =(W27/$W$11)*100 -> 56.260417 | AB27: =K27-I27 -> 349.68979 | AC27: =(I27/K27)*100 -> 92.409051 | AD27: =(AC27/$AC$28)*100 -> 99.718564 | AE27: 100
I28: 413531 | K28: 465065 | AC28: =AVERAGE(AC2:AC27) -> 92.669858
R29: =AVERAGE(R2:R27) -> 5460.0959 | S29: =AVERAGE(S2:S27) -> 104.05275 | AD29: =MIN(AD2:AD27) -> 87.4558
S30: =STDEV(S2:S27) -> 18.856231 | AD30: =MAX(AD2:AD27) -> 105.12836
Q31: * convert prices into a quantity-equalivent reponses | R31: * clean demand-shift index
A55: Demand trendline | B55: obs | C55: trend | D55: depart from trend
A65: 2009 | B65: =S11 -> 100 | C65: =(A65-2008)*0.9785+99.104 -> 100.0825 | D65: =B65-C65 -> -0.0825 | E65: =D65*3+100 -> 99.7525 | F65: 100
A66: 2010 | B66: =S12 -> 100.15076 | C66: =(A66-2008)*0.9785+99.104 -> 101.061 | D66: =B66-C66 -> -0.91024153 | E66: =D66*3+100 -> 97.269275 | F66: 100
A67: 2011 | B67: =S13 -> 97.454643 | C67: =(A67-2008)*0.9785+99.104 -> 102.0395 | D67: =B67-C67 -> -4.5848571 | E67: =D67*3+100 -> 86.245429 | F67: 100
A68: 2012 | B68: =S14 -> 97.871365 | C68: =(A68-2008)*0.9785+99.104 -> 103.018 | D68: =B68-C68 -> -5.1466351 | E68: =D68*3+100 -> 84.560095 | F68: 100
A69: 2013 | B69: =S15 -> 107.28096 | C69: =(A69-2008)*0.9785+99.104 -> 103.9965 | D69: =B69-C69 -> 3.2844604 | E69: =D69*3+100 -> 109.85338 | F69: 100
A70: 2014 | B70: =S16 -> 113.86946 | C70: =(A70-2008)*0.9785+99.104 -> 104.975 | D70: =B70-C70 -> 8.8944614 | E70: =D70*3+100 -> 126.68338 | F70: 100
A71: 2015 | B71: =S17 -> 113.61853 | C71: =(A71-2008)*0.9785+99.104 -> 105.9535 | D71: =B71-C71 -> 7.6650291 | E71: =D71*3+100 -> 122.99509 | F71: 100
A72: 2016 | B72: =S18 -> 122.46185 | C72: =(A72-2008)*0.9785+99.104 -> 106.932 | D72: =B72-C72 -> 15.529853 | E72: =D72*3+100 -> 146.58956 | F72: 100
A73: 2017 | B73: =S19 -> 124.39167 | C73: =(A73-2008)*0.9785+99.104 -> 107.9105 | D73: =B73-C73 -> 16.48117 | E73: =D73*3+100 -> 149.44351 | F73: 100
A74: 2018 | B74: =S20 -> 112.44585 | C74: =(A74-2008)*0.9785+99.104 -> 108.889 | D74: =B74-C74 -> 3.5568513 | E74: =D74*3+100 -> 110.67055 | F74: 100
A75: 2019 | B75: =S21 -> 112.22725 | C75: =(A75-2008)*0.9785+99.104 -> 109.8675 | D75: =B75-C75 -> 2.3597499 | E75: =D75*3+100 -> 107.07925 | F75: 100
...

Sheet Est. Demand Index
B1: Reported Index Value | C1: Trendline Value | D1: Dep From Demand Index Trendline
A2: 2009 | B2: 100 | C2: 100.0825 | D2: =B2-C2 -> -0.0825
A3: 2010 | B3: 106.43784 | C3: 101.061 | D3: =B3-C3 -> 5.3768374
A4: 2011 | B4: 104.52059 | C4: 102.0395 | D4: =B4-C4 -> 2.4810896
A5: 2012 | B5: 94.044222 | C5: 103.018 | D5: =B5-C5 -> -8.9737782
A6: 2013 | B6: 105.77667 | C6: 103.9965 | D6: =B6-C6 -> 1.780172
A7: 2014 | B7: 104.31318 | C7: 104.975 | D7: =B7-C7 -> -0.6618225
A8: 2015 | B8: 102.90289 | C8: 105.9535 | D8: =B8-C8 -> -3.0506116
A9: 2016 | B9: 108.92479 | C9: 106.932 | D9: =B9-C9 -> 1.9927873
A10: 2017 | B10: 109.87659 | C10: 107.9105 | D10: =B10-C10 -> 1.9660932 | H10: Year | I10: Trendline Usage | J10: Dep From Demand Index Trendline | K10: Estimated Dep from Trendline
A11: 2018 | B11: 106.87481 | C11: 108.889 | D11: =B11-C11 -> -2.0141923 | H11: 2009 | I11: =E37 -> 108.11401 | J11: =D2 -> -0.0825 | K11: =$N$28+(I11*$N$29) -> 3.7286082
A12: 2019 | B12: 103.22427 | C12: 109.8675 | D12: =B12-C12 -> -6.6432317 | H12: 2010 | I12: =E38 -> 105.97622 | J12: =D3 -> 5.3768374 | K12: =$N$28+(I12*$N$29) -> 2.686064 | M12: SUMMARY OUTPUT
A13: 2020 | B13: 114.96652 | C13: 110.846 | D13: =B13-C13 -> 4.1205195 | H13: 2011 | I13: =E39 -> 99.584459 | J13: =D4 -> 2.4810896 | K13: =$N$28+(I13*$N$29) -> -0.4310352
A14: 2021 | B14: 119.98158 | C14: 111.8245 | D14: =B14-C14 -> 8.1570751 | H14: 2012 | I14: =E40 -> 86.788625 | J14: =D5 -> -8.9737782 | K14: =$N$28+(I14*$N$29) -> -6.6712356 | M14: Regression Statistics
A15: 2022 | B15: 110.26015 | C15: 112.803 | D15: =B15-C15 -> -2.5428513 | H15: 2013 | I15: =E41 -> 103.45921 | J15: =D6 -> 1.780172 | K15: =$N$28+(I15*$N$29) -> 1.458584 | M15: Multiple R | N15: 0.64521278
A16: 2023 | B16: 112.14638 | C16: 113.7815 | D16: =B16-C16 -> -1.6351181 | H16: 2014 | I16: =E42 -> 103.83582 | J16: =D7 -> -0.6618225 | K16: =$N$28+(I16*$N$29) -> 1.6422433 | M16: R Square | N16: 0.41629953
A17: 2024 | B17: 111.71477 | C17: 114.76 | D17: =B17-C17 -> -3.0452327 | H17: 2015 | I17: =E43 -> 101.38017 | J17: =D8 -> -3.0506116 | K17: =$N$28+(I17*$N$29) -> 0.44468939 | M17: Adjusted R Square | N17: 0.37738616
A18: 2025 | B18: 118.51163 | C18: 115.7385 | D18: =B18-C18 -> 2.7731288 | H18: 2016 | I18: =E44 -> 106.82035 | J18: =D9 -> 1.9927873 | K18: =$N$28+(I18*$N$29) -> 3.0977227 | M18: Standard Error | N18: 3.3833118
H19: 2017 | I19: =E45 -> 106.0861 | J19: =D10 -> 1.9660932 | K19: =$N$28+(I19*$N$29) -> 2.7396488 | M19: Observations | N19: 17
H20: 2018 | I20: =E46 -> 100.47652 | J20: =D11 -> -2.0141923 | K20: =$N$28+(I20*$N$29) -> 0.0039980421
H21: 2019 | I21: =E47 -> 95.989528 | J21: =D12 -> -6.6432317 | K21: =$N$28+(I21*$N$29) -> -2.1841908 | M21: ANOVA
H22: 2020 | I22: =E48 -> 101.52616 | J22: =D13 -> 4.1205195 | K22: =$N$28+(I22*$N$29) -> 0.51588069 | N22: df | O22: SS | P22: MS | Q22: F | R22: Significance F
H23: 2021 | I23: =E49 -> 100.04414 | J23: =D14 -> 8.1570751 | K23: =$N$28+(I23*$N$29) -> -0.20685809 | M23: Regression | N23: 1 | O23: 122.45913 | P23: 122.45913 | Q23: 10.698112 | R23: 0.005158686
H24: 2022 | I24: =E50 -> 90.593871 | J24: =D15 -> -2.5428513 | K24: =$N$28+(I24*$N$29) -> -4.8155146 | M24: Residual | N24: 15 | O24: 171.70198 | P24: 11.446798
H25: 2023 | I25: =E51 -> 97.402917 | J25: =D16 -> -1.6351181 | K25: =$N$28+(I25*$N$29) -> -1.4949174 | M25: Total | N25: 16 | O25: 294.16111
H26: 2024 | I26: =E52 -> 97.080065 | J26: =D17 -> -3.0452327 | K26: =$N$28+(I26*$N$29) -> -1.6523638
B27: Total Usage | E27: Trendline Usage | H27: 2025 | I27: =E53 -> 102.79987 | J27: =D18 -> 2.7731288 | K27: =$N$28+(I27*$N$29) -> 1.1370408 | N27: Coefficients | O27: Standard Error | P27: t Stat | Q27: P-value | R27: Lower 95% | S27: Upper 95% | T27: Lower 95.0% | U27: Upper 95.0%
A28: 2000 | B28: 247415 | C28: =(A28-1999)*5992+246476 -> 252468 | D28: =B28-C28 -> -5053 | E28: =((D28/C28)*100)+100 -> 97.998558 | M28: Intercept | N28: -48.995826 | O28: 15.002212 | P28: -3.2659069 | Q28: 0.0052106491 | R28: -80.972284 | S28: -17.019369 | T28: -80.972284 | U28: -17.019369
A29: 2001 | B29: 249324 | C29: =(A29-1999)*5992+246476 -> 258460 | D29: =B29-C29 -> -9136 | E29: =((D29/C29)*100)+100 -> 96.465217 | M29: Trendline Usage | N29: 0.4876744 | O29: 0.14909957 | P29: 3.2707968 | Q29: 0.005158686 | R29: 0.16987619 | S29: 0.80547261 | T29: 0.16987619 | U29: 0.80547261
A30: 2002 | B30: 241082 | C30: =(A30-1999)*5992+246476 -> 264452 | D30: =B30-C30 -> -23370 | E30: =((D30/C30)*100)+100 -> 91.162858
A31: 2003 | B31: 259853 | C31: =(A31-1999)*5992+246476 -> 270444 | D31: =B31-C31 -> -10591 | E31: =((D31/C31)*100)+100 -> 96.083847
A32: 2004 | B32: 270791 | C32: =(A32-1999)*5992+246476 -> 276436 | D32: =B32-C32 -> -5645 | E32: =((D32/C32)*100)+100 -> 97.957936
A33: 2005 | B33: 286216 | C33: =(A33-1999)*5992+246476 -> 282428 | D33: =B33-C33 -> 3788 | E33: =((D33/C33)*100)+100 -> 101.34123
A34: 2006 | B34: 284661 | C34: =(A34-1999)*5992+246476 -> 288420 | D34: =B34-C34 -> -3759 | E34: =((D34/C34)*100)+100 -> 98.696692
A35: 2007 | B35: 323545 | C35: =(A35-1999)*5992+246476 -> 294412 | D35: =B35-C35 -> 29133 | E35: =((D35/C35)*100)+100 -> 109.89532
A36: 2008 | B36: 305006 | C36: =(A36-1999)*5992+246476 -> 300404 | D36: =B36-C36 -> 4602 | E36: =((D36/C36)*100)+100 -> 101.53194
A37: 2009 | B37: 331257 | C37: =(A37-1999)*5992+246476 -> 306396 | D37: =B37-C37 -> 24861 | E37: =((D37/C37)*100)+100 -> 108.11401
A38: 2010 | B38: 331057 | C38: =(A38-1999)*5992+246476 -> 312388 | D38: =B38-C38 -> 18669 | E38: =((D38/C38)*100)+100 -> 105.97622
A39: 2011 | B39: 317057 | C39: =(A39-1999)*5992+246476 -> 318380 | D39: =B39-C39 -> -1323 | E39: =((D39/C39)*100)+100 -> 99.584459
A40: 2012 | B40: 281518 | C40: =(A40-1999)*5992+246476 -> 324372 | D40: =B40-C40 -> -42854 | E40: =((D40/C40)*100)+100 -> 86.788625
...

Sheet Tool Ideas
A2: Tool #1. Estimate point price using user-inputted Supply and Usage | I2: Future Efforts
I3: --> Better demand index est (v1 in 'Est. Demand Index' worksheet | U3: Hidden calc
C4: User-input | F4: Output | I4: --> include 'is this combination of supply and usage feasible | U4: Demand Index Trend Value | V4: =C145 -> 115.7385 | X4: Trendlines Usage | Y4: ='Est. Demand Index'!$C$53 -> 402268
B5: Corn Supply | C5: 465065 | E5: Norm Demand | F5: =((((C$5/(($V6/100)*$R$75))^$O$66)/($W$75/100))*0.0323)+1.8946 -> 4.1603204 | I5: --> include a graph to show how far up/down the index/price line est are | U5: Adj | V5: =AB7+(AB8*Y5) -> 1.1370408 | X5: Trendline Usage Dep | Y5: =(C6/Y4)*100 -> 102.79987
B6: Corn Usage | C6: 413531 | U6: Assumed Demand Index | V6: =V4+V5 -> 116.87554 | AB6: FROM "Est. Demant Index" WORKSHEET
AB7: -48.995826
AB8: 0.4876744
A9: xxxx | B9: xxxxx | C9: xxxx | D9: xxxx | E9: xxxxx
A16: Tool #2. Range of Price Given Supply (unknown usage)
G18: Output
C19: User-input | G19: Avg | H19: Range | I19: Prob of Outcome
B20: Corn Supply | C20: 465065 | E20: Output | F20: Low | G20: =AVERAGE(X191) -> 3.7181196 | H20: =ROUND(MIN(U192:U197),2)&" - "&ROUND(MAX(U191:U197),2) -> 3.41 - 3.86 | I20: =AA191 -> 0.41176471
D21: Norm Demand | E21: =U199 -> 4.0247464 | F21: Mod | G21: =X192 -> 4.1760458 | H21: =ROUND(MIN(U198:U203),2)&" - "&ROUND(MAX(U198:U203),2) -> 3.96 - 4.32 | I21: =AA192 -> 0.35294118
F22: High | G22: =X193 -> 4.6630654 | H22: =ROUND(MIN(U204:U207),2)&" - "&ROUND(MAX(U204:U207),2) -> 4.35 - 5.09 | I22: =AA193 -> 0.23529412
A27: Tool #3. Source of change in price estimates (since 2004 and throughout 2025)
A28: I don't have this figure out yet
B30: Change from 2024
B32: Change in obs price | C32: =Z91-Z90 -> -0.55141881
C33: Supply | D33: Demand | H33: Change Supp | I33: change in demand
B34: 2024 | C34: =B177 -> 423610 | D34: =B144 -> 111.71477 | F34: =(((($C$34/((D34/100)*$R$75))^$O$66)/($W$75/100))*0.0324)+1.9155 -> 4.9333132
B35: 2025 | C35: =B178 -> 465065 | D35: =B145 -> 118.51163 | F35: =(((($C$35/((D35/100)*$R$75))^$O$66)/($W$75/100))*0.0324)+1.9155 -> 4.3818944 | H35: =(((($C$35/((D34/100)*$R$75))^$O$66)/($W$75/100))*0.0324)+1.9155 -> 3.6580206 | I35: =(((($C$34/((D35/100)*$R$75))^$O$66)/($W$75/100))*0.0324)+1.9155 -> 6.186966
F36: =F35-F34 -> -0.55141881 | H36: =(((($C$35/((D35/100)*$R$75))^$O$66)/($W$75/100))*0.0324)+1.9155 -> 4.3818944 | I36: =(((($C$35/((D35/100)*$R$75))^$O$66)/($W$75/100))*0.0324)+1.9155 -> 4.3818944
H37: =H35-F34 -> -1.2752926 | I37: =I35-F34 -> 1.2536528
H38: =H36-F34 -> -0.55141881 | I38: =I36-F34 -> -0.55141881
H39: =AVERAGE(H37:H38) -> -0.91335569 | I39: =AVERAGE(I37:I38) -> 0.35111699 | J39: =I39+H39 -> -0.56223871
H42: =H35-H36 -> -0.72387377 | I42: =I35-I36 -> 1.8050716 | J42: =I42+H42 -> 1.0811978
C48: Supply | D48: =(1/-0.17)*LN(C35/C34) -> -0.54919977 | E48: =EXP(D48)-1 -> -0.42258831
C49: Demand | D49: =(-1/-0.17)*LN(D35/D34) -> 0.34742463 | E49: =EXP(D49)-1 -> 0.41541762
D50: =D49+D48 -> -0.20177514
A65: Year | B65: ExchangeRate (Export Competitors - Corn) | C65: Ending Stocks | D65: World: Ending Stocks | E65: World Pop (SPPOPTOTLWLD) | F65: US pop (1000s) (B230RC0A052NBEA) | G65: USGDP (GDP) | H65: PCE Index (PCEPI) | I65: Total Usage | J65: Real MYA Price | K65: Supply | L65: Supply Index | M65: Invert Supply | N65: Elasticity | O65: -0.17 | Q65: p^-.17 (P epsolon) | R65: A | S65: Demand Index | T65: (From earlier efforts | V65: Supply/Demand Strengh | X65: S/D Index | Y65: Real MYA Price | Z65: Est
A66: 2000 | B66: 110.65269 | C66: 48240 | D66: 175136 | E66: 6161884811 | F66: 282398 | G66: 10250.952 | H66: 73.822 | I66: 247415 | J66: 3.6736133 | K66: 295655 | L66: =(K66/$K$75)*100 -> 78.917726 | M66: =100-(L66-100) -> 121.08227 | N66: inverted elasticiy | O66: =1/O65 -> -5.8823529 | P66: 2000 | Q66: =J66^$O$65 -> 0.80155645 | R66: =I66/Q66 -> 308668.22 | S66: =(R66/$R$75)*100 -> 69.886712 | V66: =K66/R66 -> 0.95784077 | W66: =V66^$O$66 -> 1.2883662 | X66: =(W66/$W$75)*100 -> 48.924871 | Y66: 3.6736133 | Z66: =X66*0.0324+1.9155 -> 3.5006658
A67: 2001 | B67: 117.24628 | C67: 40551 | D67: 151409 | E67: 6245112906 | F67: 285225 | G67: 10581.929 | H67: 75.302 | I67: 249324 | J67: 3.7917204 | K67: 289875 | L67: =(K67/$K$75)*100 -> 77.374899 | M67: =100-(L67-100) -> 122.6251 | P67: 2001 | Q67: =J67^$O$65 -> 0.79725606 | R67: =I67/Q67 -> 312727.63 | S67: =(R67/$R$75)*100 -> 70.80582 | V67: =K67/R67 -> 0.9269248 | W67: =V67^$O$66 -> 1.5626289 | X67: =(W67/$W$75)*100 -> 59.339822 | Y67: 3.7917204 | Z67: =X67*0.0324+1.9155 -> 3.8381102
A68: 2002 | B68: 103.79282 | C68: 27603 | D68: 126942 | E68: 6327557399 | F68: 287955 | G68: 10929.108 | H68: 76.291 | I68: 241082 | J68: 4.3845551 | K68: 268685 | L68: =(K68/$K$75)*100 -> 71.718757 | M68: =100-(L68-100) -> 128.28124 | O68: -0.17 | P68: 2002 | Q68: =J68^$O$65 -> 0.77780846 | R68: =I68/Q68 -> 309950.35 | S68: =(R68/$R$75)*100 -> 70.177004 | V68: =K68/R68 -> 0.86686466 | W68: =V68^$O$66 -> 2.317354 | X68: =(W68/$W$75)*100 -> 88.000016 | Y68: 4.3845551 | Z68: =X68*0.0324+1.9155 -> 4.7667005
A69: 2003 | B69: 96.601189 | C69: 24337 | D69: 104701 | E69: 6409750441 | F69: 290626 | G69: 11456.45 | H69: 77.894 | I69: 259853 | J69: 4.478966 | K69: 284190 | L69: =(K69/$K$75)*100 -> 75.85743 | M69: =100-(L69-100) -> 124.14257 | P69: 2003 | Q69: =J69^$O$65 -> 0.77499657 | R69: =I69/Q69 -> 335295.68 | S69: =(R69/$R$75)*100 -> 75.915534 | V69: =K69/R69 -> 0.84758027 | W69: =V69^$O$66 -> 2.6452436 | X69: =(W69/$W$75)*100 -> 100.45141 | Y69: 4.478966 | Z69: =X69*0.0324+1.9155 -> 5.1701257
A70: 2004 | B70: 92.980888 | C70: 53697 | D70: 131156 | E70: 6492769815 | F70: 293262 | G70: 12217.196 | H70: 79.827 | I70: 270791 | J70: 3.6874 | K70: 324488 | L70: =(K70/$K$75)*100 -> 86.613976 | M70: =100-(L70-100) -> 113.38602 | P70: 2004 | Q70: =J70^$O$65 -> 0.80104619 | R70: =I70/Q70 -> 338046.68 | S70: =(R70/$R$75)*100 -> 76.538398 | V70: =K70/R70 -> 0.95989112 | W70: =V70^$O$66 -> 1.2722622 | X70: =(W70/$W$75)*100 -> 48.313334 | Y70: 3.6874 | Z70: =X70*0.0324+1.9155 -> 3.480852
A71: 2005 | B71: 91.054237 | C71: 49968 | D71: 123418 | E71: 6575841506 | F71: 295993 | G71: 13039.197 | H71: 82.127 | I71: 286216 | J71: 3.4951185 | K71: 336184 | L71: =(K71/$K$75)*100 -> 89.735931 | M71: =100-(L71-100) -> 110.26407 | P71: 2005 | Q71: =J71^$O$65 -> 0.8083724 | R71: =I71/Q71 -> 354064.54 | S71: =(R71/$R$75)*100 -> 80.165061 | V71: =K71/R71 -> 0.94949921 | W71: =V71^$O$66 -> 1.3563903 | X71: =(W71/$W$75)*100 -> 51.508042 | Y71: 3.4951185 | Z71: =X71*0.0324+1.9155 -> 3.5843605
A72: 2006 | B72: 84.098709 | C72: 33114 | D72: 108756 | E72: 6659977025 | F72: 298818 | G72: 13815.583 | H72: 84.44 | I72: 284661 | J72: 5.1895368 | K72: 317775 | L72: =(K72/$K$75)*100 -> 84.822108 | M72: =100-(L72-100) -> 115.17789 | P72: 2006 | Q72: =J72^$O$65 -> 0.75583698 | R72: =I72/Q72 -> 376616.92 | S72: =(R72/$R$75)*100 -> 85.27123 | V72: =K72/R72 -> 0.84376187 | W72: =V72^$O$66 -> 2.7164431 | X72: =(W72/$W$75)*100 -> 103.15517 | Y72: 5.1895368 | Z72: =X72*0.0324+1.9155 -> 5.2577274
A73: 2007 | B73: 79.869598 | C73: 41255 | D73: 125362 | E73: 6744489399 | F73: 301696 | G73: 14474.227 | H73: 86.607 | I73: 323545 | J73: 6.8972477 | K73: 364800 | L73: =(K73/$K$75)*100 -> 97.374258 | M73: =100-(L73-100) -> 102.62574 | P73: 2007 | Q73: =J73^$O$65 -> 0.72015356 | R73: =I73/Q73 -> 449272.24 | S73: =(R73/$R$75)*100 -> 101.72139 | V73: =K73/R73 -> 0.81197984 | W73: =V73^$O$66 -> 3.4047622 | X73: =(W73/$W$75)*100 -> 129.29364 | Y73: 6.8972477 | Z73: =X73*0.0324+1.9155 -> 6.1046139
A74: 2008 | B74: 84.344528 | C74: 42504 | D74: 136049 | E74: 6830513541 | F74: 304543 | G74: 14769.862 | H74: 89.17 | I74: 305006 | J74: 6.3273383 | K74: 347510 | L74: =(K74/$K$75)*100 -> 92.759124 | M74: =100-(L74-100) -> 107.24088 | P74: 2008 | Q74: =J74^$O$65 -> 0.7307897 | R74: =I74/Q74 -> 417364.94 | S74: =(R74/$R$75)*100 -> 94.497139 | V74: =K74/R74 -> 0.83262864 | W74: =V74^$O$66 -> 2.9371983 | X74: =(W74/$W$75)*100 -> 111.5382 | Y74: 6.3273383 | Z74: =X74*0.0324+1.9155 -> 5.5293378
A75: 2009 | B75: 82.045845 | C75: 43380 | D75: 131485 | E75: 6916589116 | F75: 307240 | G75: 14478.067 | H75: 88.921 | I75: 331257 | J75: 5.4311966 | K75: 374637 | L75: =(K75/$K$75)*100 -> 100 | M75: =100-(L75-100) -> 100 | P75: 2009 | Q75: =J75^$O$65 -> 0.75001122 | R75: =I75/Q75 -> 441669.39 | S75: =(R75/$R$75)*100 -> 100 | T75: 100.85527 | V75: =K75/R75 -> 0.84822948 | W75: =V75^$O$66 -> 2.6333563 | X75: =(W75/$W$75)*100 -> 100 | Y75: 5.4311966 | Z75: =X75*0.0324+1.9155 -> 5.1555
...

Sheet Scoring.Eval
A1: Year | B1: ExchangeRate (Export Competitors - Corn) | C1: Ending Stocks | D1: World: Ending Stocks | E1: World Pop (SPPOPTOTLWLD) | F1: US pop (1000s) (B230RC0A052NBEA) | G1: USGDP (GDP) | H1: PCE Index (PCEPI) | I1: Total Usage | J1: Real MYA Price | K1: Supply | L1: Supply Index | M1: Invert Supply | N1: Elasticity | O1: -0.17 | Q1: p^-.17 (P epsolon) | R1: A | S1: Demand Index | T1: (From earlier efforts | V1: Supply/Demand Strengh | X1: S/D Index
A2: 2000 | B2: 110.65269 | C2: 48240 | D2: 175136 | E2: 6161884811 | F2: 282398 | G2: 10250.952 | H2: 73.822 | I2: 247415 | J2: 3.6736133 | K2: 295655 | L2: =(K2/$K$11)*100 -> 78.917726 | M2: =100-(L2-100) -> 121.08227 | N2: inverted elasticiy | O2: =1/O1 -> -5.8823529 | P2: 2000 | Q2: =J2^$O$1 -> 0.80155645 | R2: =I2/Q2 -> 308668.22 | S2: =(R2/$R$28)*100 -> 70.993801 | V2: =K2/R2 -> 0.95784077 | W2: =V2^$O$2 -> 1.2883662 | X2: =(W2/$W$11)*100 -> 48.924871
A3: 2001 | B3: 117.24628 | C3: 40551 | D3: 151409 | E3: 6245112906 | F3: 285225 | G3: 10581.929 | H3: 75.302 | I3: 249324 | J3: 3.7917204 | K3: 289875 | L3: =(K3/$K$11)*100 -> 77.374899 | M3: =100-(L3-100) -> 122.6251 | P3: 2001 | Q3: =J3^$O$1 -> 0.79725606 | R3: =I3/Q3 -> 312727.63 | S3: =(R3/$R$28)*100 -> 71.927469 | V3: =K3/R3 -> 0.9269248 | W3: =V3^$O$2 -> 1.5626289 | X3: =(W3/$W$11)*100 -> 59.339822
A4: 2002 | B4: 103.79282 | C4: 27603 | D4: 126942 | E4: 6327557399 | F4: 287955 | G4: 10929.108 | H4: 76.291 | I4: 241082 | J4: 4.3845551 | K4: 268685 | L4: =(K4/$K$11)*100 -> 71.718757 | M4: =100-(L4-100) -> 128.28124 | P4: 2002 | Q4: =J4^$O$1 -> 0.77780846 | R4: =I4/Q4 -> 309950.35 | S4: =(R4/$R$28)*100 -> 71.288692 | V4: =K4/R4 -> 0.86686466 | W4: =V4^$O$2 -> 2.317354 | X4: =(W4/$W$11)*100 -> 88.000016
A5: 2003 | B5: 96.601189 | C5: 24337 | D5: 104701 | E5: 6409750441 | F5: 290626 | G5: 11456.45 | H5: 77.894 | I5: 259853 | J5: 4.478966 | K5: 284190 | L5: =(K5/$K$11)*100 -> 75.85743 | M5: =100-(L5-100) -> 124.14257 | P5: 2003 | Q5: =J5^$O$1 -> 0.77499657 | R5: =I5/Q5 -> 335295.68 | S5: =(R5/$R$28)*100 -> 77.118128 | V5: =K5/R5 -> 0.84758027 | W5: =V5^$O$2 -> 2.6452436 | X5: =(W5/$W$11)*100 -> 100.45141
A6: 2004 | B6: 92.980888 | C6: 53697 | D6: 131156 | E6: 6492769815 | F6: 293262 | G6: 12217.196 | H6: 79.827 | I6: 270791 | J6: 3.6874 | K6: 324488 | L6: =(K6/$K$11)*100 -> 86.613976 | M6: =100-(L6-100) -> 113.38602 | P6: 2004 | Q6: =J6^$O$1 -> 0.80104619 | R6: =I6/Q6 -> 338046.68 | S6: =(R6/$R$28)*100 -> 77.750858 | V6: =K6/R6 -> 0.95989112 | W6: =V6^$O$2 -> 1.2722622 | X6: =(W6/$W$11)*100 -> 48.313334
A7: 2005 | B7: 91.054237 | C7: 49968 | D7: 123418 | E7: 6575841506 | F7: 295993 | G7: 13039.197 | H7: 82.127 | I7: 286216 | J7: 3.4951185 | K7: 336184 | L7: =(K7/$K$11)*100 -> 89.735931 | M7: =100-(L7-100) -> 110.26407 | P7: 2005 | Q7: =J7^$O$1 -> 0.8083724 | R7: =I7/Q7 -> 354064.54 | S7: =(R7/$R$28)*100 -> 81.434972 | V7: =K7/R7 -> 0.94949921 | W7: =V7^$O$2 -> 1.3563903 | X7: =(W7/$W$11)*100 -> 51.508042
A8: 2006 | B8: 84.098709 | C8: 33114 | D8: 108756 | E8: 6659977025 | F8: 298818 | G8: 13815.583 | H8: 84.44 | I8: 284661 | J8: 5.1895368 | K8: 317775 | L8: =(K8/$K$11)*100 -> 84.822108 | M8: =100-(L8-100) -> 115.17789 | P8: 2006 | Q8: =J8^$O$1 -> 0.75583698 | R8: =I8/Q8 -> 376616.92 | S8: =(R8/$R$28)*100 -> 86.622029 | V8: =K8/R8 -> 0.84376187 | W8: =V8^$O$2 -> 2.7164431 | X8: =(W8/$W$11)*100 -> 103.15517
A9: 2007 | B9: 79.869598 | C9: 41255 | D9: 125362 | E9: 6744489399 | F9: 301696 | G9: 14474.227 | H9: 86.607 | I9: 323545 | J9: 6.8972477 | K9: 364800 | L9: =(K9/$K$11)*100 -> 97.374258 | M9: =100-(L9-100) -> 102.62574 | P9: 2007 | Q9: =J9^$O$1 -> 0.72015356 | R9: =I9/Q9 -> 449272.24 | S9: =(R9/$R$28)*100 -> 103.33278 | V9: =K9/R9 -> 0.81197984 | W9: =V9^$O$2 -> 3.4047622 | X9: =(W9/$W$11)*100 -> 129.29364
A10: 2008 | B10: 84.344528 | C10: 42504 | D10: 136049 | E10: 6830513541 | F10: 304543 | G10: 14769.862 | H10: 89.17 | I10: 305006 | J10: 6.3273383 | K10: 347510 | L10: =(K10/$K$11)*100 -> 92.759124 | M10: =100-(L10-100) -> 107.24088 | P10: 2008 | Q10: =J10^$O$1 -> 0.7307897 | R10: =I10/Q10 -> 417364.94 | S10: =(R10/$R$28)*100 -> 95.994087 | V10: =K10/R10 -> 0.83262864 | W10: =V10^$O$2 -> 2.9371983 | X10: =(W10/$W$11)*100 -> 111.5382
A11: 2009 | B11: 82.045845 | C11: 43380 | D11: 131485 | E11: 6916589116 | F11: 307240 | G11: 14478.067 | H11: 88.921 | I11: 331257 | J11: 5.4311966 | K11: 374637 | L11: =(K11/$K$11)*100 -> 100 | M11: =100-(L11-100) -> 100 | P11: 2009 | Q11: =J11^$O$1 -> 0.75001122 | R11: =I11/Q11 -> 441669.39 | S11: =(R11/$R$28)*100 -> 101.58412 | T11: 100.85527 | V11: =K11/R11 -> 0.84822948 | W11: =V11^$O$2 -> 2.6333563 | X11: =(W11/$W$11)*100 -> 100
A12: 2010 | B12: 78.3582 | C12: 28644 | D12: 114858 | E12: 7001266876 | F12: 309839 | G12: 15048.971 | H12: 90.514 | I12: 331057 | J12: 7.8673212 | K12: 359701 | L12: =(K12/$K$11)*100 -> 96.013207 | M12: =100-(L12-100) -> 103.98679 | P12: 2010 | Q12: =J12^$O$1 -> 0.70422174 | R12: =I12/Q12 -> 470103.35 | S12: =(R12/$R$28)*100 -> 108.12394 | T12: 104.36824 | V12: =K12/R12 -> 0.76515303 | W12: =V12^$O$2 -> 4.8287367 | X12: =(W12/$W$11)*100 -> 183.36815
A13: 2011 | B13: 83.05545 | C13: 25122 | D13: 122848 | E13: 7087120034 | F13: 312295 | G13: 15599.732 | H13: 92.804 | I13: 317057 | J13: 9.1153918 | K13: 342179 | L13: =(K13/$K$11)*100 -> 91.336147 | M13: =100-(L13-100) -> 108.66385 | P13: 2011 | Q13: =J13^$O$1 -> 0.6868125 | R13: =I13/Q13 -> 461635.45 | S13: =(R13/$R$28)*100 -> 106.17632 | T13: 97.927618 | V13: =K13/R13 -> 0.74123207 | W13: =V13^$O$2 -> 5.8207011 | X13: =(W13/$W$11)*100 -> 221.03736
A14: 2012 | B14: 83.028945 | C14: 20859 | D14: 145530 | E14: 7176929184 | F14: 314725 | G14: 16253.97 | H14: 94.534 | I14: 281518 | J14: 9.8552169 | K14: 302377 | L14: =(K14/$K$11)*100 -> 80.711996 | M14: =100-(L14-100) -> 119.288 | P14: 2012 | Q14: =J14^$O$1 -> 0.67776127 | R14: =I14/Q14 -> 415364.54 | S14: =(R14/$R$28)*100 -> 95.533995 | T14: 72.56313 | V14: =K14/R14 -> 0.72797981 | W14: =V14^$O$2 -> 6.4723612 | X14: =(W14/$W$11)*100 -> 245.78372
A15: 2013 | B15: 86.381657 | C15: 31292 | D15: 216040 | E15: 7265892332 | F15: 317099 | G15: 16880.683 | H15: 95.781 | I15: 341792 | J15: 6.2861417 | K15: 373084 | L15: =(K15/$K$11)*100 -> 99.585465 | M15: =100-(L15-100) -> 100.41453 | P15: 2013 | Q15: =J15^$O$1 -> 0.73160168 | R15: =I15/Q15 -> 467183.18 | S15: =(R15/$R$28)*100 -> 107.4523 | T15: 89.785653 | V15: =K15/R15 -> 0.79858183 | W15: =V15^$O$2 -> 3.7548417 | X15: =(W15/$W$11)*100 -> 142.58768
A16: 2014 | B16: 99.928975 | C16: 43974 | D16: 279937 | E16: 7354068030 | F16: 319601 | G16: 17608.138 | H16: 97.121 | I16: 349258 | J16: 5.10022 | K16: 393232 | L16: =(K16/$K$11)*100 -> 104.96347 | M16: =100-(L16-100) -> 95.036529 | P16: 2014 | Q16: =J16^$O$1 -> 0.758071 | R16: =I16/Q16 -> 460719.38 | S16: =(R16/$R$28)*100 -> 105.96562 | T16: 87.842946 | V16: =K16/R16 -> 0.85351739 | W16: =V16^$O$2 -> 2.5388269 | X16: =(W16/$W$11)*100 -> 96.410307
A17: 2015 | B17: 103.52059 | C17: 44123 | D17: 313363 | E17: 7441677465 | F17: 322113 | G17: 18295.019 | H17: 97.299 | I17: 347073 | J17: 4.8848056 | K17: 391196 | L17: =(K17/$K$11)*100 -> 104.42001 | M17: =100-(L17-100) -> 95.579988 | P17: 2015 | Q17: =J17^$O$1 -> 0.76365282 | R17: =I17/Q17 -> 454490.56 | S17: =(R17/$R$28)*100 -> 104.53299 | T17: 81.84277 | V17: =K17/R17 -> 0.86073515 | W17: =V17^$O$2 -> 2.4161304 | X17: =(W17/$W$11)*100 -> 91.750987
A18: 2016 | B18: 100.41136 | C18: 58253 | D18: 350824 | E18: 7528879985 | F18: 324609 | G18: 18804.913 | H18: 98.284 | I18: 372098 | J18: 4.5318407 | K18: 430351 | L18: =(K18/$K$11)*100 -> 114.87146 | M18: =100-(L18-100) -> 85.128538 | P18: 2016 | Q18: =J18^$O$1 -> 0.7734519 | R18: =I18/Q18 -> 481087.45 | S18: =(R18/$R$28)*100 -> 110.65029 | T18: 88.936169 | V18: =K18/R18 -> 0.894538 | W18: =V18^$O$2 -> 1.9262515 | X18: =(W18/$W$11)*100 -> 73.148152
A19: 2017 | B19: 102.30157 | C19: 54367 | D19: 342235 | E19: 7614523410 | F19: 326860 | G19: 19612.103 | H19: 100 | I19: 375897 | J19: 4.4931483 | K19: 430264 | L19: =(K19/$K$11)*100 -> 114.84824 | M19: =100-(L19-100) -> 85.15176 | P19: 2017 | Q19: =J19^$O$1 -> 0.77458016 | R19: =I19/Q19 -> 485291.28 | S19: =(R19/$R$28)*100 -> 111.61717 | T19: 92.283147 | V19: =K19/R19 -> 0.88660979 | W19: =V19^$O$2 -> 2.0298117 | X19: =(W19/$W$11)*100 -> 77.080785
A20: 2018 | B20: 108.06282 | C20: 56823 | D20: 326775 | E20: 7697233736 | F20: 328794 | G20: 20656.516 | H20: 102.047 | I20: 362041 | J20: 4.7614 | K20: 418864 | L20: =(K20/$K$11)*100 -> 111.80529 | M20: =100-(L20-100) -> 88.194706 | P20: 2018 | Q20: =J20^$O$1 -> 0.76698188 | R20: =I20/Q20 -> 472033.31 | S20: =(R20/$R$28)*100 -> 108.56783 | T20: 90.264036 | V20: =K20/R20 -> 0.8873611 | W20: =V20^$O$2 -> 2.0197232 | X20: =(W20/$W$11)*100 -> 76.697679
A21: 2019 | B21: 112.25717 | C21: 50913 | D21: 314542 | E21: 7778008621 | F21: 330513 | G21: 21539.982 | H21: 103.509 | I21: 351625 | J21: 4.6081405 | K21: 402538 | L21: =(K21/$K$11)*100 -> 107.44748 | M21: =100-(L21-100) -> 92.552524 | P21: 2019 | Q21: =J21^$O$1 -> 0.77125968 | R21: =I21/Q21 -> 455910 | S21: =(R21/$R$28)*100 -> 104.85946 | T21: 87.550077 | V21: =K21/R21 -> 0.88293304 | W21: =V21^$O$2 -> 2.0800413 | X21: =(W21/$W$11)*100 -> 78.98822
A22: 2020 | B22: 110.50794 | C22: 31358 | D22: 297358 | E22: 7854748424 | F22: 331840 | G22: 21375.282 | H22: 104.666 | I22: 377990 | J22: 5.67609 | K22: 409348 | L22: =(K22/$K$11)*100 -> 109.26524 | M22: =100-(L22-100) -> 90.734765 | P22: 2020 | Q22: =J22^$O$1 -> 0.74440901 | R22: =I22/Q22 -> 507771.93 | S22: =(R22/$R$28)*100 -> 116.78773 | T22: 107.31693 | V22: =K22/R22 -> 0.80616509 | W22: =V22^$O$2 -> 3.5517889 | X22: =(W22/$W$11)*100 -> 134.87688
... A26: 2024 | B26: 115.30512 | C26: 38905 | D26: 293369 | E26: 8141808945 | F26: 340212 | G26: 29298.013 | H26: 123.666 | I26: 384705 | J26: 4.322799 | K26: 423610 | L26: =(K26/$K$11)*100 -> 113.07212 | M26: =100-(L26-100) -> 86.92788 | P26: 2024 | Q26: =J26^$O$1 -> 0.77968637 | R26: =I26/Q26 -> 493409.93 | S26: =(R26/$R$28)*100 -> 113.48446 | T26: 94.660708 | V26: =K26/R26 -> 0.85853561 | W26: =V26^$O$2 -> 2.4527708 | X26: =(W26/$W$11)*100 -> 93.142383
A27: 2025 | B27: 117.66338 | C27: 51534 | D27: 279151 | E27: =AVERAGE((E26-E25),(E25-E24),(E24-E23),(E23-E22))+E26 -> 8.2135741e+09 | F27: =AVERAGE((F26-F25),(F25-F24),(F24-F23),(F23-F22))+F26 -> 342305 | G27: =AVERAGE((G26-G25),(G25-G24),(G24-G23),(G23-G22))+G26 -> 31278.696 | H27: =AVERAGE((H26-H25),(H25-H24),(H24-H23),(H23-H22))+H26 -> 128.416 | I27: 413531 | J27: 4 | K27: 465065 | L27: =(K27/$K$11)*100 -> 124.1375 | M27: =100-(L27-100) -> 75.862502 | P27: 2025 | Q27: =J27^$O$1 -> 0.79004131 | R27: =I27/Q27 -> 523429.59 | S27: =(R27/$R$28)*100 -> 120.389 | T27: 112.57873 | V27: =K27/R27 -> 0.88849581 | W27: =V27^$O$2 -> 2.0045973 | X27: =(W27/$W$11)*100 -> 76.123284
I28: 413531 | K28: 465065 | R28: =AVERAGE(R2:R27) -> 434781.92 | S28: =(R28/$R$11)*100 -> 98.440583
T29: =CORREL(T11:T27,S11:S27) -> 0.75680497
V30: =CORREL(V2:V27,J2:J27) -> -0.92954898 | W30: =CORREL(W2:W27,J2:J27) -> 0.97634636 | X30: =CORREL(J2:J27,X2:X27) -> 0.97634636
Q31: * convert prices into a quantity-equalivent reponses | R31: * clean demand-shift index | V31: =CORREL(V2:V28,J2:J27) -> #N/A
O35: New Tool with demand known | Y35: S2U model
P37: S/D Index | Q37: Real MYA Price | R37: Est | S37: Error | Z37: S2U | AA37: Real MYA Price | AC37: Est | AD37: Error
O47: 2009 | P47: =X11 -> 100 | Q47: =J11 -> 5.4311966 | R47: =0.0323*P47+1.8946 -> 5.1246 | S47: =(R47-Q47) -> -0.30659658 | Y47: 2009 | Z47: =C11/I11 -> 0.13095572 | AA47: =J11 -> 5.4311966 | AC47: =-34.762*Z47+9.8197 -> 5.2674172 | AD47: =(AC47-AA47) -> -0.16377943
O48: 2010 | P48: =X12 -> 183.36815 | Q48: =J12 -> 7.8673212 | R48: =0.0323*P48+1.8946 -> 7.8173913 | S48: =(R48-Q48) -> -0.049929944 | Y48: 2010 | Z48: =C12/I12 -> 0.086522865 | AA48: =J12 -> 7.8673212 | AC48: =-34.762*Z48+9.8197 -> 6.8119922 | AD48: =(AC48-AA48) -> -1.055329
O49: 2011 | P49: =X13 -> 221.03736 | Q49: =J13 -> 9.1153918 | R49: =0.0323*P49+1.8946 -> 9.0341066 | S49: =(R49-Q49) -> -0.081285215 | Y49: 2011 | Z49: =C13/I13 -> 0.079234964 | AA49: =J13 -> 9.1153918 | AC49: =-34.762*Z49+9.8197 -> 7.0653342 | AD49: =(AC49-AA49) -> -2.0500576
O50: 2012 | P50: =X14 -> 245.78372 | Q50: =J14 -> 9.8552169 | R50: =0.0323*P50+1.8946 -> 9.8334143 | S50: =(R50-Q50) -> -0.021802637 | Y50: 2012 | Z50: =C14/I14 -> 0.074094729 | AA50: =J14 -> 9.8552169 | AC50: =-34.762*Z50+9.8197 -> 7.244019 | AD50: =(AC50-AA50) -> -2.6111979
O51: 2013 | P51: =X15 -> 142.58768 | Q51: =J15 -> 6.2861417 | R51: =0.0323*P51+1.8946 -> 6.5001821 | S51: =(R51-Q51) -> 0.2140404 | Y51: 2013 | Z51: =C15/I15 -> 0.091552757 | AA51: =J15 -> 6.2861417 | AC51: =-34.762*Z51+9.8197 -> 6.6371431 | AD51: =(AC51-AA51) -> 0.35100132
O52: 2014 | P52: =X16 -> 96.410307 | Q52: =J16 -> 5.10022 | R52: =0.0323*P52+1.8946 -> 5.0086529 | S52: =(R52-Q52) -> -0.091567093 | Y52: 2014 | Z52: =C16/I16 -> 0.12590692 | AA52: =J16 -> 5.10022 | AC52: =-34.762*Z52+9.8197 -> 5.4429236 | AD52: =(AC52-AA52) -> 0.34270353
O53: 2015 | P53: =X17 -> 91.750987 | Q53: =J17 -> 4.8848056 | R53: =0.0323*P53+1.8946 -> 4.8581569 | S53: =(R53-Q53) -> -0.026648728 | Y53: 2015 | Z53: =C17/I17 -> 0.12712887 | AA53: =J17 -> 4.8848056 | AC53: =-34.762*Z53+9.8197 -> 5.4004461 | AD53: =(AC53-AA53) -> 0.51564043
O54: 2016 | P54: =X18 -> 73.148152 | Q54: =J18 -> 4.5318407 | R54: =0.0323*P54+1.8946 -> 4.2572853 | S54: =(R54-Q54) -> -0.27455538 | Y54: 2016 | Z54: =C18/I18 -> 0.15655284 | AA54: =J18 -> 4.5318407 | AC54: =-34.762*Z54+9.8197 -> 4.3776101 | AD54: =(AC54-AA54) -> -0.15423064
O55: 2017 | P55: =X19 -> 77.080785 | Q55: =J19 -> 4.4931483 | R55: =0.0323*P55+1.8946 -> 4.3843094 | S55: =(R55-Q55) -> -0.10883899 | Y55: 2017 | Z55: =C19/I19 -> 0.14463271 | AA55: =J19 -> 4.4931483 | AC55: =-34.762*Z55+9.8197 -> 4.7919779 | AD55: =(AC55-AA55) -> 0.29882955
O56: 2018 | P56: =X20 -> 76.697679 | Q56: =J20 -> 4.7614 | R56: =0.0323*P56+1.8946 -> 4.371935 | S56: =(R56-Q56) -> -0.38946498 | Y56: 2018 | Z56: =C20/I20 -> 0.15695184 | AA56: =J20 -> 4.7614 | AC56: =-34.762*Z56+9.8197 -> 4.3637402 | AD56: =(AC56-AA56) -> -0.39765976
...
